Workbook

Sheet Master_104_Matches
A1: match_id | B1: match_date | C1: stage | D1: group | E1: team_a | F1: team_b | G1: fifa_rank_diff | H1: elo_rating_diff | I1: last5_avg_goals_scored_diff | J1: last5_avg_goals_conceded_diff | K1: last5_win_rate_diff | L1: last5_clean_sheet_rate_diff | M1: rest_days_diff | N1: last5_opponent_strength_diff | O1: team_a_goals | P1: team_b_goals | Q1: result_note | R1: goal_difference
A2: 1 | B2: 46184 | C2: Group Stage | D2: A | E2: Mexico | F2: South Africa | G2: =X1_X2_Inputs!E2-X1_X2_Inputs!F2 -> -46 | H2: =X1_X2_Inputs!G2-X1_X2_Inputs!H2 -> 358 | I2: 1 | J2: -0.6 | K2: 0.4 | L2: 0.2 | M2: 2 | N2: -34 | O2: 2 | P2: 0 | R2: =O2-P2 -> 2
A3: 2 | B3: 46184 | C3: Group Stage | D3: A | E3: Korea Republic | F3: Czechia | G3: =X1_X2_Inputs!E3-X1_X2_Inputs!F3 -> -15 | H3: =X1_X2_Inputs!G3-X1_X2_Inputs!H3 -> 18 | I3: -2 | J3: -0.2 | K3: 0 | L3: 0.4 | M3: 1 | N3: -23.6 | O3: 2 | P3: 1 | R3: =O3-P3 -> 1
A4: 3 | B4: 46185 | C4: Group Stage | D4: B | E4: Canada | F4: Bosnia and Herzegovina | G4: =X1_X2_Inputs!E4-X1_X2_Inputs!F4 -> -34 | H4: =X1_X2_Inputs!G4-X1_X2_Inputs!H4 -> 193 | I4: 0.6 | J4: -0.2 | K4: 0.4 | L4: 0.4 | M4: 1 | N4: 30.4 | O4: 1 | P4: 1 | R4: =O4-P4 -> 0
A5: 4 | B5: 46185 | C5: Group Stage | D5: D | E5: USA | F5: Paraguay | G5: =X1_X2_Inputs!E5-X1_X2_Inputs!F5 -> -24 | H5: =X1_X2_Inputs!G5-X1_X2_Inputs!H5 -> -108 | I5: 0.4 | J5: 1.4 | K5: -0.2 | L5: -0.4 | M5: -1 | N5: -32.2 | O5: 4 | P5: 1 | R5: =O5-P5 -> 3
A6: 5 | B6: 46186 | C6: Group Stage | D6: C | E6: Haiti | F6: Scotland | G6: =X1_X2_Inputs!E6-X1_X2_Inputs!F6 -> 41 | H6: =X1_X2_Inputs!G6-X1_X2_Inputs!H6 -> -234 | I6: -0.8 | J6: -0.2 | K6: -0.2 | L6: 0.2 | M6: 1 | N6: 31.6 | O6: 0 | P6: 1 | R6: =O6-P6 -> -1
A7: 6 | B7: 46186 | C7: Group Stage | D7: D | E7: Australia | F7: Türkiye | G7: =X1_X2_Inputs!E7-X1_X2_Inputs!F7 -> 5 | H7: =X1_X2_Inputs!G7-X1_X2_Inputs!H7 -> -134 | I7: -0.6 | J7: 0.6 | K7: -0.4 | L7: -0.4 | M7: 0 | N7: -14.4 | O7: 2 | P7: 0 | R7: =O7-P7 -> 2
A8: 7 | B8: 46186 | C8: Group Stage | D8: C | E8: Brazil | F8: Morocco | G8: =X1_X2_Inputs!E8-X1_X2_Inputs!F8 -> -1 | H8: =X1_X2_Inputs!G8-X1_X2_Inputs!H8 -> 164 | I8: 0 | J8: 0.8 | K8: 0 | L8: -0.4 | M8: 1 | N8: -44.2 | O8: 1 | P8: 1 | R8: =O8-P8 -> 0
A9: 8 | B9: 46186 | C9: Group Stage | D9: B | E9: Qatar | F9: Switzerland | G9: =X1_X2_Inputs!E9-X1_X2_Inputs!F9 -> 37 | H9: =X1_X2_Inputs!G9-X1_X2_Inputs!H9 -> -470 | I9: -1.6 | J9: -0.2 | K9: -0.2 | L9: 0 | M9: 0 | N9: 33.2 | O9: 1 | P9: 1 | R9: =O9-P9 -> 0
A10: 9 | B10: 46187 | C10: Group Stage | D10: E | E10: Côte d'Ivoire | F10: Ecuador | G10: =X1_X2_Inputs!E10-X1_X2_Inputs!F10 -> 10 | H10: =X1_X2_Inputs!G10-X1_X2_Inputs!H10 -> -243 | I10: 0.6 | J10: 0.2 | K10: 0.2 | L10: 0.2 | M10: 3 | N10: -19.8 | O10: 1 | P10: 0 | R10: =O10-P10 -> 1
A11: 10 | B11: 46187 | C11: Group Stage | D11: E | E11: Germany | F11: Curaçao | G11: =X1_X2_Inputs!E11-X1_X2_Inputs!F11 -> -72 | H11: =X1_X2_Inputs!G11-X1_X2_Inputs!H11 -> 498 | I11: 2.4 | J11: -1.2 | K11: 0.8 | L11: 0 | M11: 0 | N11: -39 | O11: 7 | P11: 1 | R11: =O11-P11 -> 6
A12: 11 | B12: 46187 | C12: Group Stage | D12: F | E12: Netherlands | F12: Japan | G12: =X1_X2_Inputs!E12-X1_X2_Inputs!F12 -> -10 | H12: =X1_X2_Inputs!G12-X1_X2_Inputs!H12 -> 42 | I12: 0.2 | J12: 0.8 | K12: -0.4 | L12: -0.8 | M12: -8 | N12: 2.6 | O12: 2 | P12: 2 | R12: =O12-P12 -> 0
A13: 12 | B13: 46187 | C13: Group Stage | D13: F | E13: Sweden | F13: Tunisia | G13: =X1_X2_Inputs!E13-X1_X2_Inputs!F13 -> -7 | H13: =X1_X2_Inputs!G13-X1_X2_Inputs!H13 -> 84 | I13: 1.6 | J13: 0.4 | K13: 0.2 | L13: -0.4 | M13: 2 | N13: -1 | O13: 5 | P13: 1 | R13: =O13-P13 -> 4
... A73: 72 | B73: 46200 | C73: Group Stage | D73: K | E73: Congo DR | F73: Uzbekistan | G73: =X1_X2_Inputs!E73-X1_X2_Inputs!F73 -> -4 | H73: =X1_X2_Inputs!G73-X1_X2_Inputs!H73 -> -11 | I73: 0.2 | J73: -1.6 | K73: 0.2 | L73: 0.2 | M73: 0 | N73: 11.4 | O73: 3 | P73: 1 | R73: =O73-P73 -> 2
A74: 73 | B74: 46201 | C74: Round of 32 | E74: South Africa | F74: Canada | G74: =X1_X2_Inputs!E74-X1_X2_Inputs!F74 -> 30 | H74: =X1_X2_Inputs!G74-X1_X2_Inputs!H74 -> -173 | I74: -1.6 | J74: -0.2 | K74: 0 | L74: 0.2 | M74: 0 | N74: 6.6 | O74: 0 | P74: 1 | R74: =O74-P74 -> -1
A75: 74 | B75: 46202 | C75: Round of 32 | E75: Germany | F75: Paraguay | G75: =X1_X2_Inputs!E75-X1_X2_Inputs!F75 -> -31 | H75: =X1_X2_Inputs!G75-X1_X2_Inputs!H75 -> 101 | I75: 1.8 | J75: -0.2 | K75: 0.4 | L75: -0.4 | M75: 0 | N75: 4.4 | O75: 1 | P75: 1 | Q75: PSO 3-4 | R75: =O75-P75 -> 0
A76: 75 | B76: 46202 | C76: Round of 32 | E76: Netherlands | F76: Morocco | G76: =X1_X2_Inputs!E76-X1_X2_Inputs!F76 -> 1 | H76: =X1_X2_Inputs!G76-X1_X2_Inputs!H76 -> 103 | I76: 0.2 | J76: 0.4 | K76: 0 | L76: -0.4 | M76: -1 | N76: -17.4 | O76: 1 | P76: 1 | Q76: PSO 2-3 | R76: =O76-P76 -> 0
A77: 76 | B77: 46202 | C77: Round of 32 | E77: Brazil | F77: Japan | G77: =X1_X2_Inputs!E77-X1_X2_Inputs!F77 -> -12 | H77: =X1_X2_Inputs!G77-X1_X2_Inputs!H77 -> 99 | I77: 1.2 | J77: 0.2 | K77: 0.2 | L77: -0.2 | M77: 1 | N77: 4.8 | O77: 2 | P77: 1 | R77: =O77-P77 -> 1
A78: 77 | B78: 46203 | C78: Round of 32 | E78: France | F78: Sweden | G78: =X1_X2_Inputs!E78-X1_X2_Inputs!F78 -> -35 | H78: =X1_X2_Inputs!G78-X1_X2_Inputs!H78 -> 381 | I78: 0.8 | J78: -1.4 | K78: 0.6 | L78: 0.2 | M78: -1 | N78: 11.6 | O78: 3 | P78: 0 | R78: =O78-P78 -> 3
A79: 78 | B79: 46203 | C79: Round of 32 | E79: Côte d'Ivoire | F79: Norway | G79: =X1_X2_Inputs!E79-X1_X2_Inputs!F79 -> 2 | H79: =X1_X2_Inputs!G79-X1_X2_Inputs!H79 -> -175 | I79: -1 | J79: -1.2 | K79: 0.2 | L79: 0.6 | M79: 1 | N79: 6.6 | O79: 1 | P79: 2 | R79: =O79-P79 -> -1
A80: 79 | B80: 46203 | C80: Round of 32 | E80: Mexico | F80: Ecuador | G80: =X1_X2_Inputs!E80-X1_X2_Inputs!F80 -> -9 | H80: =X1_X2_Inputs!G80-X1_X2_Inputs!H80 -> 10 | I80: 1 | J80: -0.4 | K80: 0.4 | L80: 0.4 | M80: 1 | N80: -18.2 | O80: 2 | P80: 0 | R80: =O80-P80 -> 2
A81: 80 | B81: 46204 | C81: Round of 32 | E81: England | F81: Congo DR | G81: =X1_X2_Inputs!E81-X1_X2_Inputs!F81 -> -42 | H81: =X1_X2_Inputs!G81-X1_X2_Inputs!H81 -> 326 | I81: 1 | J81: -0.6 | K81: 0.6 | L81: 0.6 | M81: 0 | N81: 22.4 | O81: 2 | P81: 1 | R81: =O81-P81 -> 1
A82: 81 | B82: 46204 | C82: Round of 32 | E82: USA | F82: Bosnia and Herzegovina | G82: =X1_X2_Inputs!E82-X1_X2_Inputs!F82 -> -47 | H82: =X1_X2_Inputs!G82-X1_X2_Inputs!H82 -> 159 | I82: 1.2 | J82: 0.2 | K82: 0.4 | L82: 0 | M82: -1 | N82: -18.2 | O82: 2 | P82: 0 | R82: =O82-P82 -> 2
A83: 82 | B83: 46204 | C83: Round of 32 | E83: Belgium | F83: Senegal | G83: =X1_X2_Inputs!E83-X1_X2_Inputs!F83 -> -6 | H83: =X1_X2_Inputs!G83-X1_X2_Inputs!H83 -> 42 | I83: 0.6 | J83: -1.4 | K83: 0.4 | L83: 0.2 | M83: 0 | N83: 4.2 | O83: 3 | P83: 2 | Q83: AET | R83: =O83-P83 -> 1
A84: 83 | B84: 46205 | C84: Round of 32 | E84: Portugal | F84: Croatia | G84: =X1_X2_Inputs!E84-X1_X2_Inputs!F84 -> -6 | H84: =X1_X2_Inputs!G84-X1_X2_Inputs!H84 -> 85 | I84: 0.6 | J84: -1 | K84: 0 | L84: 0.2 | M84: 0 | N84: 2.2 | O84: 2 | P84: 1 | R84: =O84-P84 -> 1
A85: 84 | B85: 46205 | C85: Round of 32 | E85: Spain | F85: Austria | G85: =X1_X2_Inputs!E85-X1_X2_Inputs!F85 -> -22 | H85: =X1_X2_Inputs!G85-X1_X2_Inputs!H85 -> 308 | I85: 0.2 | J85: -0.8 | K85: 0 | L85: 0.2 | M85: 1 | N85: 19.2 | O85: 3 | P85: 0 | R85: =O85-P85 -> 3
A86: 85 | B86: 46205 | C86: Round of 32 | E86: Switzerland | F86: Algeria | G86: =X1_X2_Inputs!E86-X1_X2_Inputs!F86 -> -9 | H86: =X1_X2_Inputs!G86-X1_X2_Inputs!H86 -> 129 | I86: 0.4 | J86: -0.4 | K86: 0 | L86: -0.4 | M86: 3 | N86: 13.8 | O86: 2 | P86: 0 | R86: =O86-P86 -> 2
A87: 86 | B87: 46206 | C87: Round of 32 | E87: Argentina | F87: Cabo Verde | G87: =X1_X2_Inputs!E87-X1_X2_Inputs!F87 -> -66 | H87: =X1_X2_Inputs!G87-X1_X2_Inputs!H87 -> 526 | I87: 1.6 | J87: -0.8 | K87: 0.8 | L87: 0.2 | M87: -1 | N87: -5.6 | O87: 3 | P87: 2 | Q87: AET | R87: =O87-P87 -> 1
A88: 87 | B88: 46206 | C88: Round of 32 | E88: Colombia | F88: Ghana | G88: =X1_X2_Inputs!E88-X1_X2_Inputs!F88 -> -60 | H88: =X1_X2_Inputs!G88-X1_X2_Inputs!H88 -> 429 | I88: 1.2 | J88: -0.6 | K88: 0.6 | L88: 0.2 | M88: 0 | N88: 22.8 | O88: 1 | P88: 0 | R88: =O88-P88 -> 1
A89: 88 | B89: 46206 | C89: Round of 32 | E89: Australia | F89: Egypt | G89: =X1_X2_Inputs!E89-X1_X2_Inputs!F89 -> -2 | H89: =X1_X2_Inputs!G89-X1_X2_Inputs!H89 -> 58 | I89: -0.8 | J89: -0.2 | K89: -0.2 | L89: 0.2 | M89: 1 | N89: -8.4 | O89: 1 | P89: 1 | Q89: PSO 2-4 | R89: =O89-P89 -> 0
A90: 89 | B90: 46207 | C90: Round of 16 | E90: Paraguay | F90: France | G90: =X1_X2_Inputs!E90-X1_X2_Inputs!F90 -> 38 | H90: =X1_X2_Inputs!G90-X1_X2_Inputs!H90 -> -311 | I90: -1.8 | J90: 0.4 | K90: -0.6 | L90: 0.2 | M90: 1 | N90: -0.8 | O90: 0 | P90: 1 | R90: =O90-P90 -> -1
A91: 90 | B91: 46207 | C91: Round of 16 | E91: Canada | F91: Morocco | G91: =X1_X2_Inputs!E91-X1_X2_Inputs!F91 -> 23 | H91: =X1_X2_Inputs!G91-X1_X2_Inputs!H91 -> -122 | I91: 0.4 | J91: -0.2 | K91: 0 | L91: 0.2 | M91: 1 | N91: 17.6 | O91: 0 | P91: 3 | R91: =O91-P91 -> -3
A92: 91 | B92: 46208 | C92: Round of 16 | E92: Brazil | F92: Norway | G92: =X1_X2_Inputs!E92-X1_X2_Inputs!F92 -> -25 | H92: =X1_X2_Inputs!G92-X1_X2_Inputs!H92 -> 97 | I92: 0 | J92: -1.2 | K92: 0.2 | L92: 0.4 | M92: 1 | N92: 12.6 | O92: 1 | P92: 2 | R92: =O92-P92 -> -1
A93: 92 | B93: 46208 | C93: Round of 16 | E93: Mexico | F93: England | G93: =X1_X2_Inputs!E93-X1_X2_Inputs!F93 -> 10 | H93: =X1_X2_Inputs!G93-X1_X2_Inputs!H93 -> -103 | I93: 0.4 | J93: -0.4 | K93: 0.2 | L93: 0.2 | M93: 1 | N93: -5.6 | O93: 2 | P93: 3 | R93: =O93-P93 -> -1
A94: 93 | B94: 46209 | C94: Round of 16 | E94: Portugal | F94: Spain | G94: =X1_X2_Inputs!E94-X1_X2_Inputs!F94 -> 3 | H94: =X1_X2_Inputs!G94-X1_X2_Inputs!H94 -> -146 | I94: -0.2 | J94: 0.4 | K94: -0.2 | L94: -0.4 | M94: 0 | N94: -15 | O94: 0 | P94: 1 | R94: =O94-P94 -> -1
A95: 94 | B95: 46209 | C95: Round of 16 | E95: USA | F95: Belgium | G95: =X1_X2_Inputs!E95-X1_X2_Inputs!F95 -> 8 | H95: =X1_X2_Inputs!G95-X1_X2_Inputs!H95 -> -112 | I95: -0.6 | J95: 0.4 | K95: 0 | L95: 0 | M95: 0 | N95: -5.8 | O95: 1 | P95: 4 | R95: =O95-P95 -> -3
A96: 95 | B96: 46210 | C96: Round of 16 | E96: Argentina | F96: Egypt | G96: =X1_X2_Inputs!E96-X1_X2_Inputs!F96 -> -28 | H96: =X1_X2_Inputs!G96-X1_X2_Inputs!H96 -> 404 | I96: 1.4 | J96: -0.6 | K96: 0.8 | L96: 0.6 | M96: 0 | N96: 22 | O96: 3 | P96: 2 | R96: =O96-P96 -> 1
A97: 96 | B97: 46210 | C97: Round of 16 | E97: Switzerland | F97: Colombia | G97: =X1_X2_Inputs!E97-X1_X2_Inputs!F97 -> 6 | H97: =X1_X2_Inputs!G97-X1_X2_Inputs!H97 -> -66 | I97: 0.6 | J97: 0.6 | K97: -0.2 | L97: -0.6 | M97: 1 | N97: -6.4 | O97: 0 | P97: 0 | Q97: PSO 4-3 | R97: =O97-P97 -> 0
A98: 97 | B98: 46212 | C98: Quarter-finals | E98: France | F98: Morocco | G98: =X1_X2_Inputs!E98-X1_X2_Inputs!F98 -> -4 | H98: =X1_X2_Inputs!G98-X1_X2_Inputs!H98 -> 222 | I98: 0.8 | J98: -0.4 | K98: 0.4 | L98: 0.2 | M98: 0 | N98: 2.6 | O98: 2 | P98: 0 | R98: =O98-P98 -> 2
A99: 98 | B99: 46213 | C99: Quarter-finals | E99: Spain | F99: Belgium | G99: =X1_X2_Inputs!E99-X1_X2_Inputs!F99 -> -7 | H99: =X1_X2_Inputs!G99-X1_X2_Inputs!H99 -> 216 | I99: -0.8 | J99: -1 | K99: 0.2 | L99: 0.8 | M99: 0 | N99: 1.4 | O99: 2 | P99: 1 | R99: =O99-P99 -> 1
...

Sheet Data_Rules
A1: Rule | B1: Agreed definition
A2: Team A / Team B | B2: Team A is the first-listed team in the FIFA match record; Team B is the second-listed team.
A3: Difference direction | B3: All eight explanatory variables use Team A value − Team B value.
A4: Previous five matches | B4: The five most recent senior international matches completed before kickoff of the match being predicted.
A5: No data leakage | B5: Do not use the current match or any match that occurred later.
A6: FIFA ranking | B6: Use the latest official FIFA ranking publication available before kickoff.
A7: Penalty shootouts | B7: Do not add penalty-shootout kicks to goals scored, goals conceded, or goal difference.
A8: Extra time | B8: Include goals scored during extra time in the final match score and goal difference.
A9: Win rate after PSO | B9: If a historical match is level after extra time and decided by penalties, treat it as a draw for win-rate calculation.
A10: Missing data | B10: The old xG and shots-on-target predictors were replaced. Do not substitute 0 for missing values in the eight current predictors; investigate or document missingness.
A11: match_id | B11: This is an internal project identifier assigned chronologically from 1 to 104; it is not intended to represent FIFA's official match number.
A12: Target | B12: goal_difference = team_a_goals − team_b_goals.
... A17: Target versus features | B17: Goal difference = Team A goals minus Team B goals. Goal difference and the two current-match goal columns are outcomes, not explanatory variables; exclude them from X.

Sheet X1_X2_Inputs
A1: match_id | B1: match_date | C1: team_a | D1: team_b | E1: fifa_rank_a | F1: fifa_rank_b | G1: elo_a_before | H1: elo_b_before | I1: input_review_status | K1: Methodology and evidence | L1: Notes / reference
A2: 1 | B2: 46184 | C2: Mexico | D2: South Africa | E2: 14 | F2: 60 | G2: 1875 | H2: 1517 | I2: Accepted by group | K2: X1 definition | L2: FIFA rank of Team A minus FIFA rank of Team B
A3: 2 | B3: 46184 | C3: Korea Republic | D3: Czechia | E3: 25 | F3: 40 | G3: 1758 | H3: 1740 | I3: Accepted by group | K3: X2 definition | L3: Pre-match Elo of Team A minus pre-match Elo of Team B
A4: 3 | B4: 46185 | C4: Canada | D4: Bosnia and Herzegovina | E4: 30 | F4: 64 | G4: 1788 | H4: 1595 | I4: Accepted by group | K4: FIFA ranking edition | L4: 11 June 2026 (unchanged across the tournament)
A5: 4 | B5: 46185 | C5: USA | D5: Paraguay | E5: 17 | F5: 41 | G5: 1726 | H5: 1834 | I5: Accepted by group | K5: FIFA ranking source | L5: https://inside.fifa.com/fifa-world-ranking/men?dateId=id13295
A6: 5 | B6: 46186 | C6: Haiti | D6: Scotland | E6: 83 | F6: 42 | G6: 1548 | H6: 1782 | I6: Accepted by group | K6: Elo source | L6: https://www.international-football.net/tournament?compet-id=World+Cup&year=2026
A7: 6 | B7: 46186 | C7: Australia | D7: Türkiye | E7: 27 | F7: 22 | G7: 1777 | H7: 1911 | I7: Accepted by group | K7: Source workbooks | L7: Master: FIFA_Master_Dataset_X7_X8_Completed.xlsx; raw: FIFA_WC2026_104_Match_Raw_Data_with_FIFA_and_Elo.xlsx
A8: 7 | B8: 46186 | C8: Brazil | D8: Morocco | E8: 6 | F8: 7 | G8: 1991 | H8: 1827 | I8: Accepted by group | K8: Name normalization | L8: United States in teammate file displayed as USA, matching the master
A9: 8 | B9: 46186 | C9: Qatar | D9: Switzerland | E9: 56 | F9: 19 | G9: 1421 | H9: 1891 | I9: Accepted by group | K9: Elo input review | L9: Teammate-supplied Elo inputs retained unchanged and accepted by group.
A10: 9 | B10: 46187 | C10: Côte d'Ivoire | D10: Ecuador | E10: 33 | F10: 23 | G10: 1695 | H10: 1938 | I10: Accepted by group | K10: Source verification scope | L10: X1/X2 calculated from supplied rankings and Elo inputs; full independent source reconciliation not performed.
A11: 10 | B11: 46187 | C11: Germany | D11: Curaçao | E11: 10 | F11: 82 | G11: 1932 | H11: 1434 | I11: Accepted by group
A12: 11 | B12: 46187 | C12: Netherlands | D12: Japan | E12: 8 | F12: 18 | G12: 1948 | H12: 1906 | I12: Accepted by group
A13: 12 | B13: 46187 | C13: Sweden | D13: Tunisia | E13: 38 | F13: 45 | G13: 1712 | H13: 1628 | I13: Accepted by group
A14: 13 | B14: 46188 | C14: Saudi Arabia | D14: Uruguay | E14: 61 | F14: 16 | G14: 1576 | H14: 1892 | I14: Accepted by group
A15: 14 | B15: 46188 | C15: Spain | D15: Cabo Verde | E15: 2 | F15: 67 | G15: 2157 | H15: 1578 | I15: Accepted by group
A16: 15 | B16: 46188 | C16: IR Iran | D16: New Zealand | E16: 20 | F16: 85 | G16: 1772 | H16: 1562 | I16: Accepted by group
A17: 16 | B17: 46188 | C17: Belgium | D17: Egypt | E17: 9 | F17: 29 | G17: 1894 | H17: 1696 | I17: Accepted by group
A18: 17 | B18: 46189 | C18: France | D18: Senegal | E18: 3 | F18: 15 | G18: 2063 | H18: 1860 | I18: Accepted by group
A19: 18 | B19: 46189 | C19: Iraq | D19: Norway | E19: 57 | F19: 31 | G19: 1607 | H19: 1914 | I19: Accepted by group
A20: 19 | B20: 46189 | C20: Argentina | D20: Algeria | E20: 1 | F20: 28 | G20: 2115 | H20: 1772 | I20: Accepted by group
A21: 20 | B21: 46189 | C21: Austria | D21: Jordan | E21: 24 | F21: 63 | G21: 1830 | H21: 1680 | I21: Accepted by group
A22: 21 | B22: 46190 | C22: Ghana | D22: Panama | E22: 73 | F22: 34 | G22: 1510 | H22: 1730 | I22: Accepted by group
... A105: 104 | B105: 46222 | C105: Spain | D105: Argentina | E105: 2 | F105: 1 | G105: 2232 | H105: 2200 | I105: Accepted by group

Sheet X3_X5_Detail
A1: match_id | B1: match_date | C1: team_a | D1: team_b | E1: team_a_last5_goals_total | F1: team_a_last5_avg_goals | G1: team_a_last5_wins | H1: team_a_last5_win_rate | I1: team_b_last5_goals_total | J1: team_b_last5_avg_goals | K1: team_b_last5_wins | L1: team_b_last5_win_rate | M1: last5_avg_goals_scored_diff | N1: last5_win_rate_diff
A2: 1 | B2: 46184 | C2: Mexico | D2: South Africa | E2: 9 | F2: 1.8 | G2: 3 | H2: 0.6 | I2: 4 | J2: 0.8 | K2: 1 | L2: 0.2 | M2: 1 | N2: 0.4
A3: 2 | B3: 46184 | C3: Korea Republic | D3: Czechia | E3: 7 | F3: 1.4 | G3: 3 | H3: 0.6 | I3: 17 | J3: 3.4 | K3: 3 | L3: 0.6 | M3: -2 | N3: 0
A4: 3 | B4: 46185 | C4: Canada | D4: Bosnia and Herzegovina | E4: 7 | F4: 1.4 | G4: 2 | H4: 0.4 | I4: 4 | J4: 0.8 | K4: 0 | L4: 0 | M4: 0.6 | N4: 0.4
A5: 4 | B5: 46185 | C5: USA | D5: Paraguay | E5: 11 | F5: 2.2 | G5: 2 | H5: 0.4 | I5: 9 | J5: 1.8 | K5: 3 | L5: 0.6 | M5: 0.4 | N5: -0.2
A6: 5 | B6: 46186 | C6: Haiti | D6: Scotland | E6: 8 | F6: 1.6 | G6: 2 | H6: 0.4 | I6: 12 | J6: 2.4 | K6: 3 | L6: 0.6 | M6: -0.8 | N6: -0.2
A7: 6 | B7: 46186 | C7: Australia | D7: Türkiye | E7: 7 | F7: 1.4 | G7: 2 | H7: 0.4 | I7: 10 | J7: 2 | K7: 4 | L7: 0.8 | M7: -0.6 | N7: -0.4
A8: 7 | B8: 46186 | C8: Brazil | D8: Morocco | E8: 13 | F8: 2.6 | G8: 3 | H8: 0.6 | I8: 13 | J8: 2.6 | K8: 3 | L8: 0.6 | M8: 0 | N8: 0
A9: 8 | B9: 46186 | C9: Qatar | D9: Switzerland | E9: 1 | F9: 0.2 | G9: 0 | H9: 0 | I9: 9 | J9: 1.8 | K9: 1 | L9: 0.2 | M9: -1.6 | N9: -0.2
A10: 9 | B10: 46187 | C10: Côte d'Ivoire | D10: Ecuador | E10: 12 | F10: 2.4 | G10: 4 | H10: 0.8 | I10: 9 | J10: 1.8 | K10: 3 | L10: 0.6 | M10: 0.6 | N10: 0.2
A11: 10 | B11: 46187 | C11: Germany | D11: Curaçao | E11: 18 | F11: 3.6 | G11: 5 | H11: 1 | I11: 6 | J11: 1.2 | K11: 1 | L11: 0.2 | M11: 2.4 | N11: 0.8
A12: 11 | B12: 46187 | C12: Netherlands | D12: Japan | E12: 9 | F12: 1.8 | G12: 3 | H12: 0.6 | I12: 8 | J12: 1.6 | K12: 5 | L12: 1 | M12: 0.2 | N12: -0.4
A13: 12 | B13: 46187 | C13: Sweden | D13: Tunisia | E13: 10 | F13: 2 | G13: 2 | H13: 0.4 | I13: 2 | J13: 0.4 | K13: 1 | L13: 0.2 | M13: 1.6 | N13: 0.2
... A105: 104 | B105: 46222 | C105: Spain | D105: Argentina | E105: 9 | F105: 1.8 | G105: 5 | H105: 1 | I105: 14 | J105: 2.8 | K105: 5 | L105: 1 | M105: -1 | N105: 0

Sheet Last5_Evidence
A1: match_id | B1: target_date | C1: side | D1: team_master_name | E1: lag | F1: historical_date | G1: team_source_name | H1: opponent | I1: goals_for | J1: goals_against | K1: result | L1: win_indicator | M1: competition | N1: source_csv_row
A2: 1 | B2: 46184 | C2: A | D2: Mexico | E2: 1 | F2: 46177 | G2: Mexico | H2: Serbia | I2: 5 | J2: 1 | K2: W | L2: 1 | M2: Friendly | N2: 1242
A3: 1 | B3: 46184 | C3: A | D3: Mexico | E3: 2 | F3: 46172 | G3: Mexico | H3: Australia | I3: 1 | J3: 0 | K3: W | L3: 1 | M3: Friendly | N3: 1194
A4: 1 | B4: 46184 | C4: A | D4: Mexico | E4: 3 | F4: 46164 | G4: Mexico | H4: Ghana | I4: 2 | J4: 0 | K4: W | L4: 1 | M4: Friendly | N4: 1182
A5: 1 | B5: 46184 | C5: A | D5: Mexico | E5: 4 | F5: 46112 | G5: Mexico | H5: Belgium | I5: 1 | J5: 1 | K5: D | L5: 0 | M5: Friendly | N5: 1150
A6: 1 | B6: 46184 | C6: A | D6: Mexico | E6: 5 | F6: 46109 | G6: Mexico | H6: Portugal | I6: 0 | J6: 0 | K6: D | L6: 0 | M6: Friendly | N6: 1098
A7: 1 | B7: 46184 | C7: B | D7: South Africa | E7: 1 | F7: 46179 | G7: South Africa | H7: Jamaica | I7: 1 | J7: 0 | K7: W | L7: 1 | M7: Friendly | N7: 1283
A8: 1 | B8: 46184 | C8: B | D8: South Africa | E8: 2 | F8: 46171 | G8: South Africa | H8: Nicaragua | I8: 0 | J8: 0 | K8: D | L8: 0 | M8: Friendly | N8: 1191
A9: 1 | B9: 46184 | C9: B | D9: South Africa | E9: 3 | F9: 46112 | G9: South Africa | H9: Panama | I9: 1 | J9: 2 | K9: L | L9: 0 | M9: Friendly | N9: 1163
A10: 1 | B10: 46184 | C10: B | D10: South Africa | E10: 4 | F10: 46108 | G10: South Africa | H10: Panama | I10: 1 | J10: 1 | K10: D | L10: 0 | M10: Friendly | N10: 1071
A11: 1 | B11: 46184 | C11: B | D11: South Africa | E11: 5 | F11: 46026 | G11: South Africa | H11: Cameroon | I11: 1 | J11: 2 | K11: L | L11: 0 | M11: African Cup of Nations | N11: 1007
A12: 2 | B12: 46184 | C12: A | D12: Korea Republic | E12: 1 | F12: 46176 | G12: South Korea | H12: El Salvador | I12: 1 | J12: 0 | K12: W | L12: 1 | M12: Friendly | N12: 1227
A13: 2 | B13: 46184 | C13: A | D13: Korea Republic | E13: 2 | F13: 46172 | G13: South Korea | H13: Trinidad and Tobago | I13: 5 | J13: 0 | K13: W | L13: 1 | M13: Friendly | N13: 1193
... A1041: 104 | B1041: 46222 | C1041: B | D1041: Argentina | E1041: 5 | F1041: 46200 | G1041: Argentina | H1041: Jordan | I1041: 3 | J1041: 1 | K1041: W | L1041: 1 | M1041: FIFA World Cup | N1041: 1402

Sheet Used_Source_Matches
A1: source_csv_row | B1: date | C1: home_team | D1: away_team | E1: home_score | F1: away_score | G1: tournament | H1: city | I1: country | J1: neutral
A2: 701 | B2: 45943 | C2: Uzbekistan | D2: Uruguay | E2: 1 | F2: 2 | G2: Friendly | H2: Malacca City | I2: Malaysia | J2: TRUE
A3: 804 | B3: 45975 | C3: Angola | D3: Argentina | E3: 0 | F3: 2 | G3: Friendly | H3: Luanda | I3: Angola | J3: FALSE
A4: 812 | B4: 45975 | C4: Japan | D4: Ghana | E4: 2 | F4: 0 | G4: Kirin Cup | H4: Toyota | I4: Japan | J4: FALSE
A5: 829 | B5: 45976 | C5: Mexico | D5: Uruguay | E5: 0 | F5: 0 | G5: Friendly | H5: Torreón | I5: Mexico | J5: FALSE
A6: 831 | B6: 45976 | C6: United States | D6: Paraguay | E6: 2 | F6: 1 | G6: Friendly | H6: Chester | I6: United States | J6: FALSE
A7: 838 | B7: 45976 | C7: Cyprus | D7: Austria | E7: 0 | F7: 2 | G7: FIFA World Cup qualification | H7: Limassol | I7: Cyprus | J7: FALSE
A8: 853 | B8: 45977 | C8: Azerbaijan | D8: France | E8: 1 | F8: 3 | G8: FIFA World Cup qualification | H8: Baku | I8: Azerbaijan | J8: FALSE
A9: 854 | B9: 45977 | C9: Portugal | D9: Armenia | E9: 9 | F9: 1 | G9: FIFA World Cup qualification | H9: Porto | I9: Portugal | J9: FALSE
A10: 857 | B10: 45977 | C10: Italy | D10: Norway | E10: 1 | F10: 4 | G10: FIFA World Cup qualification | H10: Milan | I10: Italy | J10: FALSE
A11: 858 | B11: 45977 | C11: Albania | D11: England | E11: 0 | F11: 2 | G11: FIFA World Cup qualification | H11: Tirana | I11: Albania | J11: FALSE
A12: 867 | B12: 45978 | C12: Germany | D12: Slovakia | E12: 6 | F12: 0 | G12: FIFA World Cup qualification | H12: Leipzig | I12: Germany | J12: FALSE
A13: 869 | B13: 45978 | C13: Netherlands | D13: Lithuania | E13: 4 | F13: 0 | G13: FIFA World Cup qualification | H13: Amsterdam | I13: Netherlands | J13: FALSE
... A282: 1436 | B282: 46218 | C282: England | D282: Argentina | E282: 1 | F282: 2 | G282: FIFA World Cup | H282: Atlanta | I282: United States | J282: TRUE

Sheet X3_X5_Methodology
A1: Rule | B1: Agreed definition
A2: Team A / Team B | B2: Team A is the first-listed team in the FIFA match record; Team B is the second-listed team.
A3: Difference direction | B3: All eight explanatory variables use Team A value − Team B value.
A4: Previous five matches | B4: The five most recent senior international matches completed before kickoff of the match being predicted.
A5: No data leakage | B5: Do not use the current match or any match that occurred later.
A6: FIFA ranking | B6: Use the latest official FIFA ranking publication available before kickoff.
A7: Penalty shootouts | B7: Do not add penalty-shootout kicks to goals scored, goals conceded, or goal difference.
A8: Extra time | B8: Include goals scored during extra time in the final match score and goal difference.
A9: Win rate after PSO | B9: If a historical match is level after extra time and decided by penalties, treat it as a draw for win-rate calculation.
A10: Missing data | B10: The old xG and shots-on-target predictors were replaced. Do not substitute 0 for missing values in the eight current predictors; investigate or document missingness.
A11: match_id | B11: This is an internal project identifier assigned chronologically from 1 to 104; it is not intended to represent FIFA's official match number.
A12: Target | B12: goal_difference = team_a_goals − team_b_goals.
... A30: Name mapping | B30: USA=United States; Korea Republic=South Korea; Czechia=Czech Republic; Türkiye=Turkey; Côte d'Ivoire=Ivory Coast; Cabo Verde=Cape Verde; Congo DR=DR Congo; IR Iran=Iran.

Sheet X4_X6_Audit
A1: match_id | B1: team_a | C1: team_b | D1: Team A previous 5 (date opponent GF-GA) | E1: Team B previous 5 (date opponent GF-GA) | F1: A goals conceded (5) | G1: B goals conceded (5) | H1: A avg conceded | I1: B avg conceded | J1: X4 = A - B | K1: A clean sheets (of 5) | L1: B clean sheets (of 5) | M1: A clean-sheet rate | N1: B clean-sheet rate | O1: X6 = A - B
A2: 1 | B2: Mexico | C2: South Africa | D2: 2026-03-28 Portugal 0-0; 2026-03-31 Belgium 1-1; 2026-05-22 Ghana 2-0; 2026-05-30 Australia 1-0; 2026-06-04 Serbia 5-1 | E2: 2026-01-04 Cameroon 1-2; 2026-03-27 Panama 1-1; 2026-03-31 Panama 1-2; 2026-05-29 Nicaragua 0-0; 2026-06-06 Jamaica 1-0 | F2: 2 | G2: 5 | H2: 0.4 | I2: 1 | J2: -0.6 | K2: 3 | L2: 2 | M2: 0.6 | N2: 0.4 | O2: 0.2
A3: 2 | B3: Korea Republic | C3: Czechia | D3: 2025-11-18 Ghana 1-0; 2026-03-28 Ivory Coast 0-4; 2026-03-31 Austria 0-1; 2026-05-30 Trinidad and Tobago 5-0; 2026-06-03 El Salvador 1-0 | E3: 2025-11-17 Gibraltar 6-0; 2026-03-26 Republic of Ireland 2-2; 2026-03-31 Denmark 2-2; 2026-05-31 Kosovo 2-1; 2026-06-04 Guatemala 5-1 | F3: 5 | G3: 6 | H3: 1 | I3: 1.2 | J3: -0.2 | K3: 3 | L3: 1 | M3: 0.6 | N3: 0.2 | O3: 0.4
A4: 3 | B4: Canada | C4: Bosnia and Herzegovina | D4: 2025-11-18 Venezuela 2-0; 2026-03-28 Iceland 2-2; 2026-03-31 Tunisia 0-0; 2026-06-01 Uzbekistan 2-0; 2026-06-05 Republic of Ireland 1-1 | E4: 2025-11-18 Austria 1-1; 2026-03-26 Wales 1-1; 2026-03-31 Italy 1-1; 2026-05-29 North Macedonia 0-0; 2026-06-06 Panama 1-1 | F4: 3 | G4: 4 | H4: 0.6 | I4: 0.8 | J4: -0.2 | K4: 3 | L4: 1 | M4: 0.6 | N4: 0.2 | O4: 0.4
A5: 4 | B5: USA | C5: Paraguay | D5: 2025-11-18 Uruguay 5-1; 2026-03-28 Belgium 2-5; 2026-03-31 Portugal 0-2; 2026-05-31 Senegal 3-2; 2026-06-06 Germany 1-2 | E5: 2025-11-15 United States 1-2; 2025-11-18 Mexico 2-1; 2026-03-27 Greece 1-0; 2026-03-31 Morocco 1-2; 2026-06-05 Nicaragua 4-0 | F5: 12 | G5: 5 | H5: 2.4 | I5: 1 | J5: 1.4 | K5: 0 | L5: 2 | M5: 0 | N5: 0.4 | O5: -0.4
A6: 5 | B6: Haiti | C6: Scotland | D6: 2025-11-18 Nicaragua 2-0; 2026-03-28 Tunisia 0-1; 2026-03-31 Iceland 1-1; 2026-06-02 New Zealand 4-0; 2026-06-05 Peru 1-2 | E6: 2025-11-18 Denmark 4-2; 2026-03-28 Japan 0-1; 2026-03-31 Ivory Coast 0-1; 2026-05-30 Curaçao 4-1; 2026-06-06 Bolivia 4-0 | F6: 4 | G6: 5 | H6: 0.8 | I6: 1 | J6: -0.2 | K6: 2 | L6: 1 | M6: 0.4 | N6: 0.2 | O6: 0.2
A7: 6 | B7: Australia | C7: Türkiye | D7: 2025-11-18 Colombia 0-3; 2026-03-27 Cameroon 1-0; 2026-03-31 Curaçao 5-1; 2026-05-30 Mexico 0-1; 2026-06-06 Switzerland 1-1 | E7: 2025-11-18 Spain 2-2; 2026-03-26 Romania 1-0; 2026-03-31 Kosovo 1-0; 2026-06-01 North Macedonia 4-0; 2026-06-06 Venezuela 2-1 | F7: 6 | G7: 3 | H7: 1.2 | I7: 0.6 | J7: 0.6 | K7: 1 | L7: 3 | M7: 0.2 | N7: 0.6 | O7: -0.4
A8: 7 | B8: Brazil | C8: Morocco | D8: 2025-11-18 Tunisia 1-1; 2026-03-26 France 1-2; 2026-03-31 Croatia 3-1; 2026-05-31 Panama 6-2; 2026-06-06 Egypt 2-1 | E8: 2026-03-27 Ecuador 1-1; 2026-03-31 Paraguay 2-1; 2026-05-26 Burundi 5-0; 2026-06-02 Madagascar 4-0; 2026-06-07 Norway 1-1 | F8: 7 | G8: 3 | H8: 1.4 | I8: 0.6 | J8: 0.8 | K8: 0 | L8: 2 | M8: 0 | N8: 0.4 | O8: -0.4
A9: 8 | B9: Qatar | C9: Switzerland | D9: 2025-12-01 Palestine 0-1; 2025-12-04 Syria 1-1; 2025-12-07 Tunisia 0-3; 2026-05-28 Republic of Ireland 0-1; 2026-06-06 El Salvador 0-0 | E9: 2025-11-18 Kosovo 1-1; 2026-03-27 Germany 3-4; 2026-03-31 Norway 0-0; 2026-05-31 Jordan 4-1; 2026-06-06 Australia 1-1 | F9: 6 | G9: 7 | H9: 1.2 | I9: 1.4 | J9: -0.2 | K9: 1 | L9: 1 | M9: 0.2 | N9: 0.2 | O9: 0
A10: 9 | B10: Côte d'Ivoire | C10: Ecuador | D10: 2026-01-06 Burkina Faso 3-0; 2026-01-10 Egypt 2-3; 2026-03-28 South Korea 4-0; 2026-03-31 Scotland 1-0; 2026-06-04 France 2-1 | E10: 2025-11-18 New Zealand 2-0; 2026-03-27 Morocco 1-1; 2026-03-31 Netherlands 1-1; 2026-05-30 Saudi Arabia 2-1; 2026-06-07 Guatemala 3-0 | F10: 4 | G10: 3 | H10: 0.8 | I10: 0.6 | J10: 0.2 | K10: 3 | L10: 2 | M10: 0.6 | N10: 0.4 | O10: 0.2
A11: 10 | B11: Germany | C11: Curaçao | D11: 2025-11-17 Slovakia 6-0; 2026-03-27 Switzerland 4-3; 2026-03-30 Ghana 2-1; 2026-05-31 Finland 4-0; 2026-06-06 United States 2-1 | E11: 2025-11-18 Jamaica 0-0; 2026-03-27 China 0-2; 2026-03-31 Australia 1-5; 2026-05-30 Scotland 1-4; 2026-06-06 Aruba 4-0 | F11: 5 | G11: 11 | H11: 1 | I11: 2.2 | J11: -1.2 | K11: 2 | L11: 2 | M11: 0.4 | N11: 0.4 | O11: 0
A12: 11 | B12: Netherlands | C12: Japan | D12: 2025-11-17 Lithuania 4-0; 2026-03-27 Norway 2-1; 2026-03-31 Ecuador 1-1; 2026-06-03 Algeria 0-1; 2026-06-08 Uzbekistan 2-1 | E12: 2025-11-14 Ghana 2-0; 2025-11-18 Bolivia 3-0; 2026-03-28 Scotland 1-0; 2026-03-31 England 1-0; 2026-05-31 Iceland 1-0 | F12: 4 | G12: 0 | H12: 0.8 | I12: 0 | J12: 0.8 | K12: 1 | L12: 5 | M12: 0.2 | N12: 1 | O12: -0.8
A13: 12 | B13: Sweden | C13: Tunisia | D13: 2025-11-18 Slovenia 1-1; 2026-03-26 Ukraine 3-1; 2026-03-31 Poland 3-2; 2026-06-01 Norway 1-3; 2026-06-04 Greece 2-2 | E13: 2026-01-03 Mali 1-1; 2026-03-28 Haiti 1-0; 2026-03-31 Canada 0-0; 2026-06-01 Austria 0-1; 2026-06-06 Belgium 0-5 | F13: 9 | G13: 7 | H13: 1.8 | I13: 1.4 | J13: 0.4 | K13: 0 | L13: 2 | M13: 0 | N13: 0.4 | O13: -0.4
... A105: 104 | B105: Spain | C105: Argentina | D105: 2026-06-26 Uruguay 1-0; 2026-07-02 Austria 3-0; 2026-07-06 Portugal 1-0; 2026-07-10 Belgium 2-1; 2026-07-14 France 2-0 | E105: 2026-06-27 Jordan 3-1; 2026-07-03 Cape Verde 3-2; 2026-07-07 Egypt 3-2; 2026-07-11 Switzerland 3-1; 2026-07-15 England 2-1 | F105: 1 | G105: 7 | H105: 0.2 | I105: 1.4 | J105: -1.2 | K105: 4 | L105: 0 | M105: 0.8 | N105: 0 | O105: 0.8
A107: Method notes (X4 and X6 only):
A108: Source: martj42/international_results (github.com/martj42/international_results) - all senior men's internationals through Oct 2026; shootout goals excluded, extra-time goals included.
A109: Window: each team's 5 most recent completed matches strictly before kickoff date, any competition, current match excluded; tournament matches already played count for later rounds.
A110: X4 = avg goals conceded (A, prev 5) - avg goals conceded (B, prev 5). Negative favours Team A. X6 = clean-sheet rate (A) - clean-sheet rate (B); clean sheet = 0 goals conceded. Positive favours Team A.
A111: Master columns J and L link to this sheet (J = X4, L = X6). No other master columns were changed.

Sheet Merge_Notes
A1: FINAL MASTER DATASET — MERGE AUDIT
A3: Variable | B3: Master column | C3: Value count | D3: Data source
A4: X1 – FIFA ranking difference | B4: G | C4: =COUNT(Master_104_Matches!G2:G105) -> 104 | D4: Teammate FIFA/Elo inputs (existing X1_X2_Inputs)
A5: X2 – Elo rating difference | B5: H | C5: =COUNT(Master_104_Matches!H2:H105) -> 104 | D5: Teammate FIFA/Elo inputs (existing X1_X2_Inputs)
A6: X3 – Last-5 goals scored difference | B6: I | C6: =COUNT(Master_104_Matches!I2:I105) -> 104 | D6: X3/X5 teammate workbook (X3_X5_Detail)
A7: X4 – Last-5 goals conceded difference | B7: J | C7: =COUNT(Master_104_Matches!J2:J105) -> 104 | D7: Suraj workbook (X4_X6_Audit)
A8: X5 – Last-5 win-rate difference | B8: K | C8: =COUNT(Master_104_Matches!K2:K105) -> 104 | D8: X3/X5 teammate workbook (X3_X5_Detail)
A9: X6 – Last-5 clean-sheet-rate difference | B9: L | C9: =COUNT(Master_104_Matches!L2:L105) -> 104 | D9: Suraj workbook (X4_X6_Audit)
A10: X7 – Rest-days difference | B10: M | C10: =COUNT(Master_104_Matches!M2:M105) -> 104 | D10: Previously completed X7/X8 master
A11: X8 – Last-5 opponent strength difference | B11: N | C11: =COUNT(Master_104_Matches!N2:N105) -> 104 | D11: Previously completed X7/X8 master (Match 29 corrected)
A13: Merged match rows | B13: 104
A14: Unique match IDs | B14: 104
A15: Historical X3–X6 values reconciled | B15: 416
A16: Historical match evidence rows | B16: 1040
A18: REVIEW NOTES
A19: All 104 match IDs, match dates, Team A/B ordering, recorded scores and other fixed columns matched across source workbooks.
A20: X3 and X5 calculations match the 1,040 team-history observations in Last5_Evidence.
A21: X1 and X2 use the original teammate-provided FIFA and Elo inputs, accepted by the group. The source values and calculations were not changed during this update.
A22: X1 and X2 use the previously supplied teammate values. Seven one-point opening Elo discrepancies remain flagged in X1_X2_Inputs; investigate before final submission.
A23: X8 Match ID 29 uses corrected opponent-strength value -43.60. Remaining historical source-review qualifications are unchanged.
A24: Collection status 'Complete' indicates all eight explanatory variables are populated. It does not certify every third-party historical input.
A25: X1/X2 are formulas linked to X1_X2_Inputs; X3–X6 were imported as calculated numeric values from teammates; X7/X8 were preserved.
A26: The current match's goals and goal difference are outcome/target columns, not predictor columns for the regression.
